Workbook

Sheet Sheet1
J1: 网贷 | K1: =K44 -> 453197.49 | L1: =L44 -> 38731.09 | M1: =M44 -> 3058.65 | N1: =N44 -> 16495 | O1: =O44 -> 436702.49
J2: 个人 | K2: =K48 -> 0 | L2: =L48 -> 0 | M2: =M48 -> 0 | N2: =N48 -> 0 | O2: =O48 -> 0
E3: =SUM(E5:E43) -> 704610.67 | J3: 合计数 | K3: =SUM(K1:K2) -> 453197.49 | L3: =SUM(L1:L2) -> 38731.09 | M3: =SUM(M1:M2) -> 3058.65 | N3: =SUM(N1:N2) -> 16495 | O3: =SUM(O1:O2) -> 436702.49
A4: 序号 | B4: 放款平台 | C4: 性质 | D4: 合作方 | E4: 初始本金 | F4: 放贷日期 | G4: 借款期限 | H4: 利率 | I4: 还款方式 | J4: 逾期日期 | K4: 剩余本金 | L4: 剩余利息 | M4: 担保费 | N4: 已还 | O4: 剩余 | P4: 逾期天数 | Q4: 按年换算 | R4: 状态 | S4: 受让方 | T4: 备注1 | U4: 初次协商
A5: 1 | B5: 度小满 | C5: 网贷 | D5: 民生银行 | E5: 12500 | F5: 44821 | G5: 12 | H5: 0.234 | I5: 等额本息 | J5: 45074 | K5: 5677.7 | L5: 346.87 | N5: =SUMIFS([1]录入!$S:$S,[1]录入!$M:$M,"网贷还本",[1]录入!$R:$R,D5) -> 0 | O5: =K5-N5 -> 5677.7 | P5: =TODAY()-J5 -> 1131 | Q5: =P5/365 -> 3.0986301
A6: 2 | B6: 度小满 | C6: 网贷 | D6: 民生银行 | E6: 15000 | F6: 44823 | G6: 12 | H6: 0.234 | I6: 等额本息 | J6: 45074 | K6: 6791.27 | L6: 313.96 | N6: =SUMIFS([1]录入!$S:$S,[1]录入!$M:$M,"网贷还本",[1]录入!$R:$R,D6) -> 0 | O6: =K6-N6 -> 6791.27 | P6: =TODAY()-J6 -> 1131 | Q6: =P6/365 -> 3.0986301
A7: 3 | B7: 度小满 | C7: 网贷 | D7: 民生银行 | E7: 20000 | F7: 44824 | G7: 12 | H7: 0.234 | I7: 等额本息 | J7: 45074 | K7: 9040.46 | L7: 550.46 | N7: =SUMIFS([1]录入!$S:$S,[1]录入!$M:$M,"网贷还本",[1]录入!$R:$R,D7) -> 0 | O7: =K7-N7 -> 9040.46 | P7: =TODAY()-J7 -> 1131 | Q7: =P7/365 -> 3.0986301
A8: 4 | B8: 度小满 | C8: 网贷 | D8: 民生银行 | E8: 10300 | F8: 44879 | G8: 12 | H8: 0.234 | I8: 等额本息 | J8: 45074 | K8: 6404.13 | L8: 425.47 | N8: =SUMIFS([1]录入!$S:$S,[1]录入!$M:$M,"网贷还本",[1]录入!$R:$R,D8) -> 0 | O8: =K8-N8 -> 6404.13 | P8: =TODAY()-J8 -> 1131 | Q8: =P8/365 -> 3.0986301
A9: 5 | B9: 度小满 | C9: 网贷 | D9: 平安青岛分行 | E9: 20000 | F9: 44797 | G9: 12 | H9: 0.234 | I9: 等额本息 | J9: 45074 | K9: 7284.02 | L9: 266.51 | N9: =SUMIFS([1]录入!$S:$S,[1]录入!$M:$M,"网贷还本",[1]录入!$R:$R,D9) -> 0 | O9: =K9-N9 -> 7284.02 | P9: =TODAY()-J9 -> 1131 | Q9: =P9/365 -> 3.0986301
A10: 6 | B10: 度小满 | C10: 网贷 | D10: 平安青岛分行 | E10: 26000 | F10: 44816 | G10: 12 | H10: 0.234 | I10: 等额本息 | J10: 45074 | K10: 11904.58 | L10: 731.34 | N10: =SUMIFS([1]录入!$S:$S,[1]录入!$M:$M,"网贷还本",[1]录入!$R:$R,D10) -> 0 | O10: =K10-N10 -> 11904.58 | P10: =TODAY()-J10 -> 1131 | Q10: =P10/365 -> 3.0986301
A11: 7 | B11: 度小满 | C11: 网贷 | D11: 五矿信托 | E11: 20000 | F11: 44788 | G11: 12 | H11: 0.234 | I11: 等额本息 | J11: 45074 | K11: 7418.12 | L11: 377.46 | N11: =SUMIFS([1]录入!$S:$S,[1]录入!$M:$M,"网贷还本",[1]录入!$R:$R,D11) -> 0 | O11: =K11-N11 -> 7418.12 | P11: =TODAY()-J11 -> 1131 | Q11: =P11/365 -> 3.0986301
A12: 8 | B12: 度小满 | C12: 网贷 | D12: 五矿信托 | E12: 25000 | F12: 44819 | G12: 12 | H12: 0.234 | I12: 等额本息 | J12: 45074 | K12: 11391.91 | L12: 697.55 | N12: =SUMIFS([1]录入!$S:$S,[1]录入!$M:$M,"网贷还本",[1]录入!$R:$R,D12) -> 0 | O12: =K12-N12 -> 11391.91 | P12: =TODAY()-J12 -> 1131 | Q12: =P12/365 -> 3.0986301 | R12: 已转让 | S12: 内蒙古宜捷冠信息科技有限公司
A13: 9 | B13: 度小满 | C13: 网贷 | D13: 众邦银行 | E13: 12000 | F13: 44852 | G13: 12 | H13: 0.234 | I13: 等额本息 | J13: 45074 | K13: 6448.81 | L13: 460.26 | N13: =SUMIFS([1]录入!$S:$S,[1]录入!$M:$M,"网贷还本",[1]录入!$R:$R,D13) -> 0 | O13: =K13-N13 -> 6448.81 | P13: =TODAY()-J13 -> 1131 | Q13: =P13/365 -> 3.0986301
A14: 10 | B14: 借呗 | C14: 网贷 | D14: 重庆农商行 | E14: 9575 | F14: 44787 | G14: 12 | H14: 0.20075 | I14: 先息后本 | J14: 45092 | K14: 9575 | L14: 484.48 | N14: =SUMIFS([1]录入!$S:$S,[1]录入!$M:$M,"网贷还本",[1]录入!$R:$R,D14) -> 0 | O14: =K14-N14 -> 9575 | P14: =TODAY()-J14 -> 1113 | Q14: =P14/365 -> 3.0493151
A15: 11 | B15: 借呗 | C15: 网贷 | D15: 重庆农商行 | E15: 11000 | F15: 44725 | G15: 12 | H15: 0.146 | I15: 先息后本 | J15: 45092 | K15: 11000 | L15: 132.81 | N15: =SUMIFS([1]录入!$S:$S,[1]录入!$M:$M,"网贷还本",[1]录入!$R:$R,D15) -> 0 | O15: =K15-N15 -> 11000 | P15: =TODAY()-J15 -> 1113 | Q15: =P15/365 -> 3.0493151
A16: 12 | B16: 借呗 | C16: 网贷 | D16: 重庆农商行 | E16: 2200 | F16: 44818 | G16: 12 | H16: 0.20075 | I16: 先息后本 | J16: 45092 | K16: 2200 | L16: 148.83 | N16: =SUMIFS([1]录入!$S:$S,[1]录入!$M:$M,"网贷还本",[1]录入!$R:$R,D16) -> 0 | O16: =K16-N16 -> 2200 | P16: =TODAY()-J16 -> 1113 | Q16: =P16/365 -> 3.0493151
A17: 13 | B17: 借呗 | C17: 网贷 | D17: 重庆农商行 | E17: 10400 | F17: 44848 | G17: 12 | H17: 0.20075 | I17: 先息后本 | J17: 45092 | K17: 10400 | L17: 875.16 | N17: =SUMIFS([1]录入!$S:$S,[1]录入!$M:$M,"网贷还本",[1]录入!$R:$R,D17) -> 0 | O17: =K17-N17 -> 10400 | P17: =TODAY()-J17 -> 1113 | Q17: =P17/365 -> 3.0493151
A18: 14 | B18: 借呗 | C18: 网贷 | D18: 重庆农商行 | E18: 12825 | F18: 44909 | G18: 12 | H18: 0.20075 | I18: 先息后本 | J18: 45092 | K18: 12825 | L18: 1509.47 | N18: =SUMIFS([1]录入!$S:$S,[1]录入!$M:$M,"网贷还本",[1]录入!$R:$R,D18) -> 0 | O18: =K18-N18 -> 12825 | P18: =TODAY()-J18 -> 1113 | Q18: =P18/365 -> 3.0493151
A19: 15 | B19: 网商贷 | C19: 网贷 | D19: 浙江网商银行 | E19: 30000 | F19: 45025 | G19: 24 | H19: 0.1764 | I19: 等额本金 | J19: 45116 | K19: 25000 | L19: 2056.79 | N19: =SUMIFS([1]录入!$S:$S,[1]录入!$M:$M,"网贷还本",[1]录入!$R:$R,D19) -> 10530 | O19: =K19-N19 -> 14470 | P19: =TODAY()-J19 -> 1089 | Q19: =P19/365 -> 2.9835616
A20: 16 | B20: 花呗 | C20: 网贷 | E20: =2818.56-228.01 -> 2590.55 | F20: 44946 | G20: 12 | I20: 等额本息 | J20: 45097 | K20: 1726.96 | L20: 152 | N20: =SUMIFS([1]录入!$S:$S,[1]录入!$M:$M,"网贷还本",[1]录入!$R:$R,D20) -> 0 | O20: =K20-N20 -> 1726.96 | P20: =TODAY()-J20 -> 1108 | Q20: =P20/365 -> 3.0356164 | T20: 未见合同
A21: 17 | B21: 花呗 | C21: 网贷 | E21: =5821.39-470.88 -> 5350.51 | F21: 44910 | G21: 12 | I21: 等额本息 | J21: 45097 | K21: 3121.09 | L21: 274.68 | N21: =SUMIFS([1]录入!$S:$S,[1]录入!$M:$M,"网贷还本",[1]录入!$R:$R,D21) -> 0 | O21: =K21-N21 -> 3121.09 | P21: =TODAY()-J21 -> 1108 | Q21: =P21/365 -> 3.0356164 | T21: 未见合同
A22: 18 | B22: 花呗 | C22: 网贷 | E22: =6821.37-551.76 -> 6269.61 | F22: 44882 | G22: 12 | I22: 等额本息 | J22: 45097 | K22: 3134.76 | L22: 275.88 | N22: =SUMIFS([1]录入!$S:$S,[1]录入!$M:$M,"网贷还本",[1]录入!$R:$R,D22) -> 0 | O22: =K22-N22 -> 3134.76 | P22: =TODAY()-J22 -> 1108 | Q22: =P22/365 -> 3.0356164 | T22: 未见合同
A23: 19 | B23: 小芽贷 | C23: 网贷 | D23: 中邮 | E23: 25000 | F23: 45042 | G23: 24 | I23: 等额本息 | J23: 45133 | K23: 23342.08 | L23: 5779.95 | N23: =SUMIFS([1]录入!$S:$S,[1]录入!$M:$M,"网贷还本",[1]录入!$R:$R,D23) -> 0 | O23: =K23-N23 -> 23342.08 | P23: =TODAY()-J23 -> 1072 | Q23: =P23/365 -> 2.9369863 | T23: 未见合同
A24: 20 | B24: 京东 | C24: 网贷 | D24: 中航信托 | E24: 9900 | F24: 44925 | G24: 12 | H24: 0.217156 | I24: 等额本息 | J24: 45076 | K24: 6600 | L24: 801.84 | N24: =SUMIFS([1]录入!$S:$S,[1]录入!$M:$M,"网贷还本",[1]录入!$R:$R,D24) -> 0 | O24: =K24-N24 -> 6600 | P24: =TODAY()-J24 -> 1129 | Q24: =P24/365 -> 3.0931507
A25: 21 | B25: 京东 | C25: 网贷 | D25: 中航信托 | E25: 10000 | F25: 44925 | G25: 12 | H25: 0.217156 | I25: 等额本息 | J25: 45076 | K25: 6666.64 | L25: 809.92 | N25: =SUMIFS([1]录入!$S:$S,[1]录入!$M:$M,"网贷还本",[1]录入!$R:$R,D25) -> 0 | O25: =K25-N25 -> 6666.64 | P25: =TODAY()-J25 -> 1129 | Q25: =P25/365 -> 3.0931507
A26: 22 | B26: 京东 | C26: 网贷 | D26: 中航信托 | E26: 12000 | F26: 44926 | G26: 12 | H26: 0.217156 | I26: 等额本息 | J26: 45077 | K26: 8000 | L26: 971.92 | N26: =SUMIFS([1]录入!$S:$S,[1]录入!$M:$M,"网贷还本",[1]录入!$R:$R,D26) -> 0 | O26: =K26-N26 -> 8000 | P26: =TODAY()-J26 -> 1128 | Q26: =P26/365 -> 3.090411
A27: 23 | B27: 京东 | C27: 网贷 | D27: 厦门国际 | E27: 24000 | F27: 44899 | G27: 12 | H27: 0.217156 | I27: 等额本息 | J27: 45081 | K27: 14000 | L27: 1700.86 | N27: =SUMIFS([1]录入!$S:$S,[1]录入!$M:$M,"网贷还本",[1]录入!$R:$R,D27) -> 0 | O27: =K27-N27 -> 14000 | P27: =TODAY()-J27 -> 1124 | Q27: =P27/365 -> 3.0794521
A28: 24 | B28: 京东 | C28: 网贷 | D28: 厦门国际 | E28: 3000 | F28: 44930 | G28: 12 | H28: 0.217207 | I28: 等额本息 | J28: 45081 | K28: 2000 | L28: 242.96 | N28: =SUMIFS([1]录入!$S:$S,[1]录入!$M:$M,"网贷还本",[1]录入!$R:$R,D28) -> 0 | O28: =K28-N28 -> 2000 | P28: =TODAY()-J28 -> 1124 | Q28: =P28/365 -> 3.0794521
A29: 25 | B29: 京东 | C29: 网贷 | D29: 中航信托 | E29: 5000 | F29: 44939 | G29: 12 | H29: 0.21715 | I29: 等额本息 | J29: 45090 | K29: 3333.36 | L29: 404.96 | N29: =SUMIFS([1]录入!$S:$S,[1]录入!$M:$M,"网贷还本",[1]录入!$R:$R,D29) -> 0 | O29: =K29-N29 -> 3333.36 | P29: =TODAY()-J29 -> 1115 | Q29: =P29/365 -> 3.0547945
A30: 26 | B30: 京东 | C30: 网贷 | D30: 中航信托 | E30: 9300 | F30: 44942 | G30: 12 | H30: 0.217167 | I30: 等额本息 | J30: 45093 | K30: 6200 | L30: 753.2 | N30: =SUMIFS([1]录入!$S:$S,[1]录入!$M:$M,"网贷还本",[1]录入!$R:$R,D30) -> 0 | O30: =K30-N30 -> 6200 | P30: =TODAY()-J30 -> 1112 | Q30: =P30/365 -> 3.0465753
A31: 27 | B31: 京东 | C31: 网贷 | D31: 中航信托 | E31: 19400 | F31: 44883 | G31: 12 | H31: 0.23725 | I31: 等额本息 | J31: 45095 | K31: 9700.02 | L31: 1262 | N31: =SUMIFS([1]录入!$S:$S,[1]录入!$M:$M,"网贷还本",[1]录入!$R:$R,D31) -> 0 | O31: =K31-N31 -> 9700.02 | P31: =TODAY()-J31 -> 1110 | Q31: =P31/365 -> 3.0410959
A32: 28 | B32: 京东 | C32: 网贷 | D32: 中航信托 | E32: 13000 | F32: 44827 | G32: 12 | H32: 0.217165 | I32: 等额本息 | J32: 45100 | K32: 4333.32 | L32: 526.44 | N32: =SUMIFS([1]录入!$S:$S,[1]录入!$M:$M,"网贷还本",[1]录入!$R:$R,D32) -> 0 | O32: =K32-N32 -> 4333.32 | P32: =TODAY()-J32 -> 1105 | Q32: =P32/365 -> 3.0273973
A33: 29 | B33: 京东 | C33: 网贷 | D33: 中航信托 | E33: 2000 | F33: 44870 | G33: 12 | H33: 0.23725 | I33: 等额本息 | J33: 45174 | K33: 500.01 | L33: 91.74 | N33: =SUMIFS([1]录入!$S:$S,[1]录入!$M:$M,"网贷还本",[1]录入!$R:$R,D33) -> 0 | O33: =K33-N33 -> 500.01 | P33: =TODAY()-J33 -> 1031 | Q33: =P33/365 -> 2.8246575
A34: 30 | B34: 京东 | C34: 网贷 | D34: 中航信托 | E34: 10000 | F34: 44851 | G34: 12 | H34: 0.23725 | I34: 等额本息 | J34: 45186 | K34: 1241.82 | L34: 264.06 | N34: =SUMIFS([1]录入!$S:$S,[1]录入!$M:$M,"网贷还本",[1]录入!$R:$R,D34) -> 0 | O34: =K34-N34 -> 1241.82 | P34: =TODAY()-J34 -> 1019 | Q34: =P34/365 -> 2.7917808
A35: 31 | B35: 招联 | C35: 网贷 | D35: 招联消费 | E35: 20000 | F35: 44882 | G35: 36 | H35: 0.228125 | I35: 等额本息 | J35: 45134 | K35: 17187.6 | L35: 5343.29 | N35: =SUMIFS([1]录入!$S:$S,[1]录入!$M:$M,"网贷还本",[1]录入!$R:$R,D35) -> 0 | O35: =K35-N35 -> 17187.6 | P35: =TODAY()-J35 -> 1071 | Q35: =P35/365 -> 2.9342466 | R35: 已转让 | S35: 吉林省盛融资产管理有限责任公司 | U35: 29160.79 | V35: =SUM(K35:K37) -> 47804.58 | W35: =U35/V35 -> 0.60999992
A36: 32 | B36: 招联 | C36: 网贷 | D36: 招联消费 | E36: 30000 | F36: 44704 | G36: 24 | H36: 0.228125 | I36: 等额本息 | J36: 45134 | K36: 15272.4 | L36: 1766.78 | N36: =SUMIFS([1]录入!$S:$S,[1]录入!$M:$M,"网贷还本",[1]录入!$R:$R,D36) -> 0 | O36: =K36-N36 -> 15272.4 | P36: =TODAY()-J36 -> 1071 | Q36: =P36/365 -> 2.9342466 | R36: 已转让 | S36: 吉林省盛融资产管理有限责任公司
A37: 33 | B37: 招联 | C37: 网贷 | D37: 招联消费 | E37: 50000 | F37: 44598 | G37: 24 | H37: 0.1095 | I37: 等额本息 | J37: 45134 | K37: 15344.58 | L37: 525.4 | N37: =SUMIFS([1]录入!$S:$S,[1]录入!$M:$M,"网贷还本",[1]录入!$R:$R,D37) -> 0 | O37: =K37-N37 -> 15344.58 | P37: =TODAY()-J37 -> 1071 | Q37: =P37/365 -> 2.9342466 | R37: 已转让 | S37: 吉林省盛融资产管理有限责任公司
A38: 34 | B38: 还呗 | C38: 网贷 | D38: 浦发银行 | E38: 40000 | F38: 44953 | G38: 12 | J38: 45073 | K38: 30226.99 | L38: 624.46 | M38: 2518.78 | N38: =SUMIFS([1]录入!$S:$S,[1]录入!$M:$M,"网贷还本",[1]录入!$R:$R,D38) -> 0 | O38: =K38-N38 -> 30226.99 | P38: =TODAY()-J38 -> 1132 | Q38: =P38/365 -> 3.1013699 | R38: 已转让 | S38: 青岛同盛益开信息科技有限公司 | T38: 按日计息，未见合同 | W38: =V35-U35 -> 18643.79
A39: 35 | B39: 还呗 | C39: 网贷 | D39: 浦发银行 | E39: 20000 | F39: 44953 | G39: 12 | J39: 45073 | K39: 14402.96 | L39: 386.74 | M39: 539.87 | N39: =SUMIFS([1]录入!$S:$S,[1]录入!$M:$M,"网贷还本",[1]录入!$R:$R,D39) -> 0 | O39: =K39-N39 -> 14402.96 | P39: =TODAY()-J39 -> 1132 | Q39: =P39/365 -> 3.1013699 | R39: 已转让 | S39: 青岛同盛益开信息科技有限公司 | T39: 按日计息，未见合同 | V39: =V35*0.4 -> 19121.832
A40: 36 | B40: 美团 | C40: 网贷 | D40: 中信百信 | E40: 6500 | F40: 44923 | G40: 12 | H40: 0.234 | I40: 等额本息 | J40: 45112 | K40: 3973.36 | L40: 315.9 | N40: =SUMIFS([1]录入!$S:$S,[1]录入!$M:$M,"网贷还本",[1]录入!$R:$R,D40) -> 0 | O40: =K40-N40 -> 3973.36 | P40: =TODAY()-J40 -> 1093 | Q40: =P40/365 -> 2.9945205
...
